<?xml version='1.0' encoding='utf-8'?>
<sdf version="1.6">
  <model name="costar_husky_sensor_config_1">
    <link name="base_link">
      <pose frame="">0 0 0 0 0 1.5708</pose> 
      <inertial>
        <pose frame="">0 0 0.062329 0 -0 1.5708</pose>
        <mass>46.064</mass>
        <inertia>
          <ixx>0.615397</ixx>
          <ixy>-0.0240585</ixy>
          <ixz>-0.120749</ixz>
          <iyy>1.75388</iyy>
          <iyz>-0.0028322</iyz>
          <izz>2.03641</izz>
        </inertia>
      </inertial>
      <collision name="base_link_collision">
        <pose frame="">0 0 0.12 0 0 1.5708</pose>
        <geometry>
          <box>
            <size>0.9874 0.5709 0.05</size>
          </box>
        </geometry>
      </collision>
      <collision name="base_link_collision_bottom">
        <pose frame="">0 0 0.046 0 0 1.5708</pose>
        <geometry>
          <box>
            <size>0.80 0.5709 0.095</size>
          </box>
        </geometry>
      </collision>
      <collision name="base_link_collision_1">
        <pose frame="">0 0 0.185625 0 -0 1.5708</pose>
        <geometry>
          <box>
            <size>0.78992 0.5709 0.12375</size>
          </box>
        </geometry>
      </collision>
      <collision name="base_link_fixed_joint_lump__top_plate_link_collision_3">
        <pose frame="">0.0812 0 0.245 0 -0 1.5708</pose>
        <geometry>
          <mesh>
            <scale>1 1 1</scale>
            <uri>meshes/top_plate.dae</uri>
          </mesh>
        </geometry>
      </collision>
      <collision name="base_link_fixed_joint_lump__top_plate_link_collision_4">
        <pose frame="">0.0812 0 0.245 0 -0 1.5708</pose>
        <geometry>
          <box>
            <size>0.32 0.41 0.09</size>
          </box>
        </geometry>
      </collision>
      <visual name="base_link_visual">
        <pose frame="">0 0 0 0 -0 1.5708</pose>
        <geometry>
          <mesh>
            <scale>1 1 1</scale>
            <uri>meshes/base_link.dae</uri>
          </mesh>
        </geometry>
      </visual>
      <visual name="base_link_fixed_joint_lump__top_chassis_link_visual_5">
        <pose frame="">0 0 0 0 -0 1.5708</pose>
        <geometry>
          <mesh>
            <scale>1 1 1</scale>
            <uri>meshes/top_chassis.dae</uri>
          </mesh>
        </geometry>
      </visual>
      <visual name="base_link_fixed_joint_lump__top_plate_link_visual_6">
        <pose frame="">0.0812 0 0.245 0 -0 1.5708</pose>
        <geometry>
          <mesh>
            <scale>1 1 1</scale>
            <uri>meshes/top_plate.dae</uri>
          </mesh>
        </geometry>
      </visual>
      
      <velocity_decay />
      <self_collide>0</self_collide>
      <enable_wind>0</enable_wind>
      <kinematic>0</kinematic>
      <gravity>1</gravity>
      <velocity_decay />
      <gravity>1</gravity>
      <velocity_decay />

      <sensor type="camera" name="right">
        <update_rate>30</update_rate>
        <always_on>true</always_on>
        <ignition_frame_id>/world/field/model/costar_husky_sensor_config_1/link/base_link</ignition_frame_id>
        <pose frame="">0.0212 0 0.950 0 0 0</pose>
        <topic>/world/field/model/costar_husky_sensor_config_1/link/base_link/stereo_camera/right/image_raw</topic>
        <camera name="right">
          <horizontal_fov>1.3962634</horizontal_fov>
          <image>
              <width>1080</width>
              <height>1920</height>
              <format>R8G8B8</format>
          </image>
          <clip>
              <near>0.02</near>
              <far>300</far>
          </clip>
        </camera>
      </sensor>

      <sensor type="camera" name="left">
        <topic>/world/field/model/costar_husky_sensor_config_1/link/base_link/stereo_camera/left/image_raw</topic>
        <update_rate>30</update_rate>
        <always_on>true</always_on>
        <ignition_frame_id>/world/field/model/costar_husky_sensor_config_1/link/base_link</ignition_frame_id>
        <pose frame="">0.0212 0.12 0.950 0 0 0</pose>
        <camera name="left">
          <horizontal_fov>1.3962634</horizontal_fov>
          <image>
              <width>1080</width>
              <height>1920</height>
              <format>R8G8B8</format>
          </image>
          <clip>
              <near>0.02</near>
              <far>300</far>
          </clip>
        </camera>
      </sensor>

      <sensor name="realsense_d435" type="rgbd_camera">
        <update_rate>30</update_rate>
        <pose frame="">0.0012 0 0.950 0 -0.3 0</pose>
        <camera name="camera">
          <horizontal_fov>1.3962634</horizontal_fov>
          <lens>
            <intrinsics>
              <!-- fx = fy = width / ( 2 * tan (hfov / 2 ) ) -->
              <fx>554.25469</fx>
              <fy>554.25469</fy>
              <!-- cx = ( width + 1 ) / 2 -->
              <cx>320.5</cx>
              <!-- cy = ( height + 1 ) / 2 -->
              <cy>240.5</cy>
              <s>0</s>
            </intrinsics>
          </lens>
          <distortion>
            <k1>0.0</k1>
            <k2>0.0</k2>
            <k3>0.0</k3>
            <p1>0.0</p1>
            <p2>0.0</p2>
            <center>0.5 0.5</center>
          </distortion>
          <image>
            <width>1080</width>
            <height>1920</height>
            <format>R8G8B8</format>
          </image>
          <clip>
            <near>0.01</near>
            <far>300</far>
          </clip>
          <depth_camera>
            <clip>
              <near>0.1</near>
              <far>10</far>
            </clip>
          </depth_camera>
          <noise>
            <type>gaussian</type>
            <mean>0</mean>
            <stddev>0.007</stddev>
          </noise>
        </camera>
      </sensor>
      
      <velocity_decay />

      <!-- GPS -->
      <sensor name="gps" type="navsat">
        <spherical_coordinates>-34.67093619854793 -56.34362977503078 0</spherical_coordinates>
      </sensor>

      <sensor name="imu_sensor" type="imu">
        <always_on>1</always_on>
        <update_rate>50</update_rate>
        <imu>
          <enable_orientation>0</enable_orientation>
          <angular_velocity>
            <x>
              <noise type="gaussian">
                <mean>0</mean>
                <stddev>0.009</stddev>
                <bias_mean>0.00075</bias_mean>
                <bias_stddev>0.005</bias_stddev>
                <dynamic_bias_stddev>0.00002</dynamic_bias_stddev>
                <dynamic_bias_correlation_time>400.0</dynamic_bias_correlation_time>
                <precision>0.00025</precision>
              </noise>
            </x>
            <y>
              <noise type="gaussian">
                <mean>0</mean>
                <stddev>0.009</stddev>
                <bias_mean>0.00075</bias_mean>
                <bias_stddev>0.005</bias_stddev>
                <dynamic_bias_stddev>0.00002</dynamic_bias_stddev>
                <dynamic_bias_correlation_time>400.0</dynamic_bias_correlation_time>
                <precision>0.00025</precision>
              </noise>
            </y>
            <z>
              <noise type="gaussian">
                <mean>0</mean>
                <stddev>0.009</stddev>
                <bias_mean>0.00075</bias_mean>
                <bias_stddev>0.005</bias_stddev>
                <dynamic_bias_stddev>0.00002</dynamic_bias_stddev>
                <dynamic_bias_correlation_time>400.0</dynamic_bias_correlation_time>
                <precision>0.00025</precision>
              </noise>
            </z>
          </angular_velocity>
          <linear_acceleration>
            <x>
              <noise type="gaussian">
                <mean>0</mean>
                <stddev>0.021</stddev>
                <bias_mean>0.05</bias_mean>
                <bias_stddev>0.0075</bias_stddev>
                <dynamic_bias_stddev>0.000375</dynamic_bias_stddev>
                <dynamic_bias_correlation_time>175.0</dynamic_bias_correlation_time>
                <precision>0.005</precision>
              </noise>
            </x>
            <y>
              <noise type="gaussian">
                <mean>0</mean>
                <stddev>0.021</stddev>
                <bias_mean>0.05</bias_mean>
                <bias_stddev>0.0075</bias_stddev>
                <dynamic_bias_stddev>0.000375</dynamic_bias_stddev>
                <dynamic_bias_correlation_time>175.0</dynamic_bias_correlation_time>
                <precision>0.005</precision>
              </noise>
            </y>
            <z>
              <noise type="gaussian">
                <mean>0</mean>
                <stddev>0.021</stddev>
                <bias_mean>0.05</bias_mean>
                <bias_stddev>0.0075</bias_stddev>
                <dynamic_bias_stddev>0.000375</dynamic_bias_stddev>
                <dynamic_bias_correlation_time>175.0</dynamic_bias_correlation_time>
                <precision>0.005</precision>
              </noise>
            </z>
          </linear_acceleration>
        </imu>
      </sensor>
    </link>
    <link name="front_left_wheel_link">
      <pose frame="">0.256 0.2854 0.03282 0 -0 1.5708</pose>
      <inertial>
        <pose frame="">0 0 0 0 -0 1.5708</pose>
        <mass>2.637</mass>
      </inertial>
      <collision name="front_left_wheel_link_collision">
        <pose frame="">0 0 0 1.5707963267948966 -0 1.5708</pose>
        <geometry>
          <cylinder>
            <length>0.1143</length>
            <radius>0.1651</radius>
          </cylinder>
        </geometry>
        <surface>
          <contact>
            <ode>
              <kp>1e+07</kp>
              <kd>1</kd>
            </ode>
          </contact>
          <friction>
            <ode>
              <mu>0.5</mu>
              <mu2>1</mu2>
              <slip1>0.00062</slip1>
              <slip2>0</slip2>
              <fdir1>0 0 1</fdir1>
            </ode>
          </friction>
        </surface>
      </collision>
      <visual name="front_left_wheel_link_visual">
        <pose frame="">0 0 0 0 -0 1.5708</pose>
        <geometry>
          <mesh>
            <scale>1 1 1</scale>
            <uri>meshes/wheel.dae</uri>
          </mesh>
        </geometry>
      </visual>
      <gravity>1</gravity>
      <velocity_decay />
    </link>
    <joint name="front_left_wheel_joint" type="revolute">
      <child>front_left_wheel_link</child>
      <parent>base_link</parent>
      <axis>
        <xyz>0 1 0</xyz>
        <limit>
          <lower>-1e+16</lower>
          <upper>1e+16</upper>
        </limit>
        <dynamics>
          <spring_reference>0</spring_reference>
          <spring_stiffness>0</spring_stiffness>
        </dynamics>
        <use_parent_model_frame>1</use_parent_model_frame>
      </axis>
    </joint>
    <link name="front_right_wheel_link">
      <pose frame="">0.256 -0.2854 0.03282 0 -0 1.5708</pose>
      <inertial>
        <pose frame="">0 0 0 0 -0 1.5708</pose>
        <mass>2.637</mass>
      </inertial>
      <collision name="front_right_wheel_link_collision">
        <pose frame="">0 0 0 1.5707963267948966 -0 1.5708</pose>
        <geometry>
          <cylinder>
            <length>0.1143</length>
            <radius>0.1651</radius>
          </cylinder>
        </geometry>
        <surface>
          <contact>
            <ode>
              <kp>1e+07</kp>
              <kd>1</kd>
            </ode>
          </contact>
          <friction>
            <ode>
              <mu>0.5</mu>
              <mu2>1</mu2>
              <slip1>0.00062</slip1>
              <slip2>0</slip2>
              <fdir1>0 0 1</fdir1>
            </ode>
          </friction>
        </surface>
      </collision>
      <visual name="front_right_wheel_link_visual">
        <pose frame="">0 0 0 0 -0 1.5708</pose>
        <geometry>
          <mesh>
            <scale>1 1 1</scale>
            <uri>meshes/wheel.dae</uri>
          </mesh>
        </geometry>
      </visual>
      <gravity>1</gravity>
      <velocity_decay />
    </link>
    <joint name="front_right_wheel_joint" type="revolute">
      <child>front_right_wheel_link</child>
      <parent>base_link</parent>
      <axis>
        <xyz>0 1 0</xyz>
        <limit>
          <lower>-1e+16</lower>
          <upper>1e+16</upper>
        </limit>
        <dynamics>
          <spring_reference>0</spring_reference>
          <spring_stiffness>0</spring_stiffness>
        </dynamics>
        <use_parent_model_frame>1</use_parent_model_frame>
      </axis>
    </joint>
    <link name="rear_left_wheel_link">
      <pose frame="">-0.256 0.2854 0.03282 0 -0 1.5708</pose>
      <inertial>
        <pose frame="">0 0 0 0 -0 1.5708</pose>
        <mass>2.637</mass>
      </inertial>
      <collision name="rear_left_wheel_link_collision">
        <pose frame="">0 0 0 1.5707963267948966 -0 1.5708</pose>
        <geometry>
          <cylinder>
            <length>0.1143</length>
            <radius>0.1651</radius>
          </cylinder>
        </geometry>
        <surface>
          <contact>
            <ode>
              <kp>1e+07</kp>
              <kd>1</kd>
            </ode>
          </contact>
          <friction>
            <ode>
              <mu>0.5</mu>
              <mu2>1</mu2>
              <slip1>0.00062</slip1>
              <slip2>0</slip2>
              <fdir1>0 0 1</fdir1>
            </ode>
          </friction>
        </surface>
      </collision>
      <visual name="rear_left_wheel_link_visual">
        <pose frame="">0 0 0 0 -0 1.5708</pose>
        <geometry>
          <mesh>
            <scale>1 1 1</scale>
            <uri>meshes/wheel.dae</uri>
          </mesh>
        </geometry>
      </visual>
      <gravity>1</gravity>
      <velocity_decay />
    </link>
    <joint name="rear_left_wheel_joint" type="revolute">
      <child>rear_left_wheel_link</child>
      <parent>base_link</parent>
      <axis>
        <xyz>0 1 0</xyz>
        <limit>
          <lower>-1e+16</lower>
          <upper>1e+16</upper>
        </limit>
        <dynamics>
          <spring_reference>0</spring_reference>
          <spring_stiffness>0</spring_stiffness>
        </dynamics>
        <use_parent_model_frame>1</use_parent_model_frame>
      </axis>
    </joint>
    <link name="rear_right_wheel_link">
      <pose frame="">-0.256 -0.2854 0.03282 0 -0 1.5708</pose>
      <inertial>
        <pose frame="">0 0 0 0 -0 1.5708</pose>
        <mass>2.637</mass>
      </inertial>
      <collision name="rear_right_wheel_link_collision">
        <pose frame="">0 0 0 1.5707963267948966 -0 1.5708</pose>
        <geometry>
          <cylinder>
            <length>0.1143</length>
            <radius>0.1651</radius>
          </cylinder>
        </geometry>
        <surface>
          <contact>
            <ode>
              <kp>1e+07</kp>
              <kd>1</kd>
            </ode>
          </contact>
          <friction>
            <ode>
              <mu>0.5</mu>
              <mu2>1</mu2>
              <slip1>0.00062</slip1>
              <slip2>0</slip2>
              <fdir1>0 0 1</fdir1>
            </ode>
          </friction>
        </surface>
      </collision>
      <visual name="rear_right_wheel_link_visual">
        <pose frame="">0 0 0 0 -0 1.5708</pose>
        <geometry>
          <mesh>
            <scale>1 1 1</scale>
            <uri>meshes/wheel.dae</uri>
          </mesh>
        </geometry>
      </visual>
      <gravity>1</gravity>
      <velocity_decay />
    </link>
    <joint name="rear_right_wheel_joint" type="revolute">
      <child>rear_right_wheel_link</child>
      <parent>base_link</parent>
      <axis>
        <xyz>0 1 0</xyz>
        <limit>
          <lower>-1e+16</lower>
          <upper>1e+16</upper>
        </limit>
        <dynamics>
          <spring_reference>0</spring_reference>
          <spring_stiffness>0</spring_stiffness>
        </dynamics>
        <use_parent_model_frame>1</use_parent_model_frame>
      </axis>
    </joint>
    <static>0</static>
  </model>
</sdf>
